<?xml version="1.0"?>
<mujoco>
  <compiler angle="radian" meshdir="assets" autolimits="true"/>
  <asset>
    <material name="gray" rgba="0.4 0.4 0.4 1"/>
    <material name="yellow" rgba="0.866667 0.866667 0.0509804 1"/>
    <material name="light_orange" rgba="1 0.749 0 1"/>
    <material name="green" rgba="0.11 1 0 0.2"/>
    <mesh file="/Users/mohammadhamid/Mujoco/Models/Leap MJCF/Leap/assets/dip.stl"/>
    <mesh file="/Users/mohammadhamid/Mujoco/Models/Leap MJCF/Leap/assets/pip.stl"/>
    <mesh file="/Users/mohammadhamid/Mujoco/Models/Leap MJCF/Leap/assets/fingertip.stl"/>
    <mesh file="/Users/mohammadhamid/Mujoco/Models/Leap MJCF/Leap/assets/mcp_joint.stl"/>
  </asset>
  <default>
    <default class="finger">
      <material specular="0.5" shininess="0.25"/>
      <default class="visual">
        <geom type="mesh" contype="0" conaffinity="0" group="2"/>
      </default>
      <joint axis="0 0 -1" damping="2000"/>
      <default class="joint1">
        <joint range="-0.314 2.23"/>
        <general ctrlrange="-0.314 2.23"/>
      </default>
      <default class="joint2">
        <joint range="-1.047 1.047"/>
        <general ctrlrange="-1.047 1.047"/>
      </default>
      <default class="joint3">
        <joint range="-0.506 1.885"/>
        <general ctrlrange="-0.506 1.885"/>
      </default>
      <default class="joint4">
        <joint range="-0.366 2.042"/>
        <general ctrlrange="-0.366 2.042"/>
      </default>
    </default>
  </default>
  <worldbody>
    <body name="knuckle_FF" pos="0 0 0" quat="0 0 0 1">
      <joint name="j0_FF" class="joint1"/>
      <inertial mass="0.044" pos="0 0 0" diaginertia="1.47756e-05 1.31982e-05 6.0802e-06"/>
      <geom class="visual" pos="0.0084069 0.00776624 0.0146574" quat="1 0 0 0" mesh="mcp_joint" material="gray"/>
      <body name="proximal_FF" pos="-0.0122 0.0381 0.0145" quat="0.5 -0.5 -0.5 0.5">
        <joint name="j1_FF" class="joint2"/>
        <inertial mass="0.032" pos="0 0 0" diaginertia="4.7981e-06 4.23406e-06 2.86184e-06"/>
        <geom class="visual" pos="0.00964336 0.0003 0.000784034" quat="0.5 -0.5 -0.5 -0.5" mesh="pip" material="yellow"/>
        <body name="middle_FF" pos="0.015 0.0143 -0.013" quat="0.5 0.5 -0.5 0.5">
          <joint name="j2_FF" class="joint3"/>
          <inertial mass="0.037" pos="0 0 0" diaginertia="6.68256e-06 6.24841e-06 5.02002e-06"/>
          <geom class="visual" pos="0.0211334 -0.00843212 0.00978509" quat="0 -1 0 0" mesh="dip" material="yellow"/>
          <body name="distal_FF" pos="-4.08806e-09 -0.0361 0.0002">
            <joint name="j3_FF" class="joint4"/>
            <inertial mass="0.016" pos="0 0 0" diaginertia="3.37527e-06 2.863e-06 1.54873e-06"/>
            <geom class="visual" pos="0.0132864 -0.00611424 0.0145" quat="0 1 0 0" mesh="fingertip" material="yellow"/>
          </body>
        </body>
      </body>
    </body>
  </worldbody>
  <actuator>
    <position name="actuator1" joint="j0_FF" class="joint1" kp="2000"/>
    <position name="actuator2" joint="j1_FF" class="joint2" kp="2000"/>
    <position name="actuator3" joint="j2_FF" class="joint3" kp="2000"/>
    <position name="actuator4" joint="j3_FF" class="joint4" kp="2000"/>
  </actuator>
</mujoco>
