<mujoco model="Leap">
  <compiler angle="radian" meshdir="assets" autolimits="true"/>
  <visual>
    <headlight diffuse="0.6 0.6 0.6" ambient="0.3 0.3 0.3" specular="0 0 0"/>
    <rgba haze="0.15 0.25 0.35 1"/>
    <global azimuth="60" elevation="-20"/>
  </visual>
  
  <asset>
    <mesh name="palm_lower" file="palm_lower.stl"/>
    <mesh name="mcp_joint" file="mcp_joint.stl"/>
    <mesh name="pip" file="pip.stl"/>
    <mesh name="dip" file="dip.stl"/>
    <mesh name="fingertip" file="fingertip.stl"/>
    <mesh name="thumb_pip" file="thumb_pip.stl"/>
    <mesh name="thumb_dip" file="thumb_dip.stl"/>
    <mesh name="thumb_fingertip" file="thumb_fingertip.stl"/>
  </asset>

  <worldbody>
   
    
      <body name="pip_4" pos="-0.0693952 -0.00124224 -0.0216224" quat="0.707107 0 0.707107 0">
        <inertial pos="0 0 0" quat="0.709913 0.704273 -0.000363156 0.00475427" mass="0.032" diaginertia="4.7981e-06 4.23406e-06 2.86184e-06"/>
        <joint name="12" pos="0 0 0" axis="0 0 -1" range="-0.349 2.094"/>
        <geom pos="-0.00535664 0.0003 0.000784034" quat="0.5 -0.5 -0.5 -0.5" type="mesh" rgba="0.74902 0.74902 0.74902 1" mesh="pip"/>
      
        <body name="thumb_pip" pos="0 0.0143 -0.013" quat="0.5 0.5 -0.5 0.5">
          <inertial pos="0 0 0" mass="0.003" diaginertia="5.93e-07 5.49e-07 2.24e-07"/>
          <joint name="13" pos="0 0 0" axis="0 0 -1" range="-0.47 2.443"/>
          <geom pos="0.0119619 0 -0.0158526" quat="0.707107 0.707107 0 0" type="mesh" rgba="0.866667 0.866667 0.0509804 1" mesh="thumb_pip"/>
        
          <body name="thumb_dip" pos="0 0.0145 -0.017" quat="0.707107 -0.707107 0 0">
            <inertial pos="0 0 0" quat="0.708624 0.704906 0.00637342 0.0303153" mass="0.038" diaginertia="8.48742e-06 7.67823e-06 3.82835e-06"/>
            <joint name="14" pos="0 0 0" axis="0 0 -1" range="-1.2 1.9"/>
            <geom pos="0.0439687 0.057953 -0.00862868" quat="1 0 0 0" type="mesh" rgba="0.866667 0.866667 0.0509804 1" mesh="thumb_dip"/>
         
            <body name="thumb_fingertip" pos="0 0.0466 0.0002" quat="0 0 0 1">
              <inertial pos="0 0 0" quat="0.704307 0.709299 0.006848 -0.0282727" mass="0.049" diaginertia="2.03882e-05 1.98443e-05 4.32049e-06"/>
              <joint name="15" pos="0 0 0" axis="0 0 -1" range="-1.34 1.88"/>
              <geom pos="0.0625595 0.0784597 0.0489929" type="mesh" rgba="0.603922 0.14902 0.14902 1" mesh="thumb_fingertip"/>
            </body>
          </body>
        </body>
      </body>
    

  </worldbody>
</mujoco>
