<?xml version="1.0"?>
<mujoco>
  <compiler angle="radian" meshdir="assets" autolimits="true"/>
  <asset>
    <material name="gray" rgba="0.4 0.4 0.4 1"/>
    <material name="yellow" rgba="0.866667 0.866667 0.0509804 1"/>
    <material name="light_orange" rgba="1 0.749 0 1"/>
    <material name="green" rgba="0.11 1 0 0.2"/>
    <mesh file="/Users/mohammadhamid/Mujoco/Models/Leap MJCF/Leap/assets/pip.stl"/>
    <mesh file="/Users/mohammadhamid/Mujoco/Models/Leap MJCF/Leap/assets/thumb_pip.stl"/>
    <mesh file="/Users/mohammadhamid/Mujoco/Models/Leap MJCF/Leap/assets/thumb_dip.stl"/>
    <mesh file="/Users/mohammadhamid/Mujoco/Models/Leap MJCF/Leap/assets/thumb_fingertip.stl"/>
  </asset>
  <default>
    <default class="thumb">
      <material specular="0.5" shininess="0.25"/>
      <default class="visual">
        <geom type="mesh" contype="0" conaffinity="0" group="2"/>
      </default>
      <joint axis="0 0 -1" damping="2000"/>
    </default>
  </default>
  <worldbody>
    <body name="knuckle_TH" pos="0 0 0" quat="0 0 0 1" childclass="thumb">
      <joint name="j0_TH" range="-0.349 2.094"/>
      <inertial mass="0.032" pos="0 0 0" diaginertia="4.7981e-06 4.23406e-06 2.86184e-06"/>
      <geom class="visual" pos="-0.00535664 0.0003 0.000784034" quat="0.5 -0.5 -0.5 -0.5" mesh="pip" material="yellow"/>
      <body name="proximal_TH" pos="0 0.0143 -0.013" quat="0.5 0.5 -0.5 0.5">
        <joint name="j1_TH" range="-0.47 2.443"/>
        <inertial mass="0.003" pos="0 0 0" diaginertia="5.93e-07 5.49e-07 2.24e-07"/>
        <geom class="visual" pos="0.0119619 0 -0.0158526" quat="0.707107 0.707107 0 0" mesh="thumb_pip" material="yellow"/>
        <body name="middle_TH" pos="0 0.0145 -0.017" quat="0.707107 -0.707107 0 0">
          <joint name="j2_TH" range="-1.2 1.9"/>
          <inertial mass="0.038" pos="0 0 0" diaginertia="8.48742e-06 7.67823e-06 3.82835e-06"/>
          <geom class="visual" pos="0.0439687 0.057953 -0.00862868" quat="1 0 0 0" mesh="thumb_dip" material="yellow"/>
          <body name="distal_TH" pos="0 0.0466 0.0002" quat="0 0 0 1">
            <joint name="j3_TH" range="-1.34 1.88"/>
            <inertial mass="0.049" pos="0 0 0" diaginertia="2.03882e-05 1.98443e-05 4.32049e-06"/>
            <geom class="visual" pos="0.0625595 0.0784597 0.0489929" mesh="thumb_fingertip" material="yellow"/>
          </body>
        </body>
      </body>
    </body>
  </worldbody>
  <actuator>
    <position name="actuator1" joint="j0_TH" ctrlrange="-0.349 2.094" kp="2000"/>
    <position name="actuator2" joint="j1_TH" ctrlrange="-0.47 2.443" kp="2000"/>
    <position name="actuator3" joint="j2_TH" ctrlrange="-1.2 1.9" kp="2000"/>
    <position name="actuator4" joint="j3_TH" ctrlrange="-1.34 1.88" kp="2000"/>
  </actuator>
</mujoco>
